Workbook
Name tgr: 'DCF 2nd way'!$D$10
Name UPDATE: 'Data Sheet'!$E$1
Name wacc: 'DCF 2nd way'!$D$9

Sheet Model ->

Sheet Main Financials
B8: YEARS | D8: ='Data Sheet'!E16 -> 43921 | E8: ='Data Sheet'!F16 -> 44286 | F8: ='Data Sheet'!G16 -> 44651 | G8: ='Data Sheet'!H16 -> 45016 | H8: ='Data Sheet'!I16 -> 45382 | I8: ='Data Sheet'!J16 -> 45747 | J8: ='Data Sheet'!K16 -> 46112
A10: # | B10: Income Statement
B11: ='Data Sheet'!A17 -> Sales | D11: =IFERROR('Data Sheet'!E17,"-") -> 1134.21 | E11: =IFERROR('Data Sheet'!F17,"-") -> 1376.18 | F11: =IFERROR('Data Sheet'!G17,"-") -> 1490.84 | G11: =IFERROR('Data Sheet'!H17,"-") -> 1852.14 | H11: =IFERROR('Data Sheet'!I17,"-") -> 2177.41 | I11: =IFERROR('Data Sheet'!J17,"-") -> 2622.85 | J11: =IFERROR('Data Sheet'!K17,"-") -> 2950.94
B12: Sales Growth | E12: =(E11-D11)/D11 -> 0.21333792 | F12: =(F11-E11)/E11 -> 0.083317589 | G12: =(G11-F11)/F11 -> 0.2423466 | H12: =(H11-G11)/G11 -> 0.17561847 | I12: =(I11-H11)/H11 -> 0.20457332 | J12: =(J11-I11)/I11 -> 0.12508912
B14: COGS | D14: =IFERROR(SUM('Data Sheet'!E18,'Data Sheet'!E20:E22)-1*'Data Sheet'!E19,0) -> 782.38 | E14: =IFERROR(SUM('Data Sheet'!F18,'Data Sheet'!F20:F22)-1*'Data Sheet'!F19,0) -> 842.83 | F14: =IFERROR(SUM('Data Sheet'!G18,'Data Sheet'!G20:G22)-1*'Data Sheet'!G19,0) -> 968.44 | G14: =IFERROR(SUM('Data Sheet'!H18,'Data Sheet'!H20:H22)-1*'Data Sheet'!H19,0) -> 1203.97 | H14: =IFERROR(SUM('Data Sheet'!I18,'Data Sheet'!I20:I22)-1*'Data Sheet'!I19,0) -> 1456 | I14: =IFERROR(SUM('Data Sheet'!J18,'Data Sheet'!J20:J22)-1*'Data Sheet'!J19,0) -> 1674.2 | J14: =IFERROR(SUM('Data Sheet'!K18,'Data Sheet'!K20:K22)-1*'Data Sheet'!K19,0) -> 1908.17
B15: COGS % OF Sales | D15: =D14/D11 -> 0.68980171 | E15: =E14/E11 -> 0.61244169 | F15: =F14/F11 -> 0.64959352 | G15: =G14/G11 -> 0.65004265 | H15: =H14/H11 -> 0.66868435 | I15: =I14/I11 -> 0.63831329 | J15: =J14/J11 -> 0.64663124
B17: Gross Profit | D17: =D11-D14 -> 351.83 | E17: =E11-E14 -> 533.35 | F17: =F11-F14 -> 522.4 | G17: =G11-G14 -> 648.17 | H17: =H11-H14 -> 721.41 | I17: =I11-I14 -> 948.65 | J17: =J11-J14 -> 1042.77
B18: Gross Profit % Of Sales | D18: =D17/D11 -> 0.31019829 | E18: =E17/E11 -> 0.38755831 | F18: =F17/F11 -> 0.35040648 | G18: =G17/G11 -> 0.34995735 | H18: =H17/H11 -> 0.33131565 | I18: =I17/I11 -> 0.36168671 | J18: =J17/J11 -> 0.35336876
B20: Selling & General Expenses | D20: =IFERROR(SUM('Data Sheet'!E23:E24),0) -> 159.58 | E20: =IFERROR(SUM('Data Sheet'!F23:F24),0) -> 193.72 | F20: =IFERROR(SUM('Data Sheet'!G23:G24),0) -> 263.51 | G20: =IFERROR(SUM('Data Sheet'!H23:H24),0) -> 308.58 | H20: =IFERROR(SUM('Data Sheet'!I23:I24),0) -> 262.83 | I20: =IFERROR(SUM('Data Sheet'!J23:J24),0) -> 415.94 | J20: =IFERROR(SUM('Data Sheet'!K23:K24),0) -> 441.91
B21: S&G Exp % of Sales | D21: =D20/D11 -> 0.14069705 | E21: =E20/E11 -> 0.14076647 | F21: =F20/F11 -> 0.1767527 | G21: =G20/G11 -> 0.16660728 | H21: =H20/H11 -> 0.12070763 | I21: =I20/I11 -> 0.15858322 | J21: =J20/J11 -> 0.14975228
B23: EBITDA | D23: =D17-D20 -> 192.25 | E23: =E17-E20 -> 339.63 | F23: =F17-F20 -> 258.89 | G23: =G17-G20 -> 339.59 | H23: =H17-H20 -> 458.58 | I23: =I17-I20 -> 532.71 | J23: =J17-J20 -> 600.86
B24: EBITDA % Of Sales | D24: =D23/D11 -> 0.16950124 | E24: =E23/E11 -> 0.24679184 | F24: =F23/F11 -> 0.17365378 | G24: =G23/G11 -> 0.18335007 | H24: =H23/H11 -> 0.21060802 | I24: =I23/I11 -> 0.20310349 | J24: =J23/J11 -> 0.20361647
B26: Interest | D26: =IFERROR('Data Sheet'!E27,0) -> 8.75 | E26: =IFERROR('Data Sheet'!F27,0) -> 7.99 | F26: =IFERROR('Data Sheet'!G27,0) -> 8.45 | G26: =IFERROR('Data Sheet'!H27,0) -> 9.13 | H26: =IFERROR('Data Sheet'!I27,0) -> 11.2 | I26: =IFERROR('Data Sheet'!J27,0) -> 11.66 | J26: =IFERROR('Data Sheet'!K27,0) -> 24.13
B27: Interest % Of Sales | D27: =D26/D11 -> 0.0077146207 | E27: =E26/E11 -> 0.0058059266 | F27: =F26/F11 -> 0.0056679456 | G27: =G26/G11 -> 0.004929433 | H27: =H26/H11 -> 0.0051437258 | I27: =I26/I11 -> 0.0044455459 | J27: =J26/J11 -> 0.0081770554
B29: Depriciation | D29: =IFERROR('Data Sheet'!E26,0) -> 26.66 | E29: =IFERROR('Data Sheet'!F26,0) -> 36.15 | F29: =IFERROR('Data Sheet'!G26,0) -> 44.78 | G29: =IFERROR('Data Sheet'!H26,0) -> 51.85 | H29: =IFERROR('Data Sheet'!I26,0) -> 74.27 | I29: =IFERROR('Data Sheet'!J26,0) -> 83.39 | J29: =IFERROR('Data Sheet'!K26,0) -> 98.63
B30: Depriciation % Of Sales | D30: =D29/D11 -> 0.023505347 | E30: =E29/E11 -> 0.026268366 | F30: =F29/F11 -> 0.030036758 | G30: =G29/G11 -> 0.027994644 | H30: =H29/H11 -> 0.034109332 | I30: =I29/I11 -> 0.03179366 | J30: =J29/J11 -> 0.033423248
B32: Earnings Before Tax | D32: ='Data Sheet'!E28 -> 157.17 | E32: ='Data Sheet'!F28 -> 302.17 | F32: ='Data Sheet'!G28 -> 247.51 | G32: ='Data Sheet'!H28 -> 337.66 | H32: ='Data Sheet'!I28 -> 423.53 | I32: ='Data Sheet'!J28 -> 503.96 | J32: ='Data Sheet'!K28 -> 560.56
B33: EBT % Of Sales | D33: =D32/D11 -> 0.13857222 | E33: =E32/E11 -> 0.21957157 | F33: =F32/F11 -> 0.1660205 | G33: =G32/G11 -> 0.18230803 | H33: =H32/H11 -> 0.19451091 | I33: =I32/I11 -> 0.19214214 | J33: =J32/J11 -> 0.18995981
B35: Tax | D35: =IFERROR('Data Sheet'!E29,0) -> 36.42 | E35: =IFERROR('Data Sheet'!F29,0) -> 63.62 | F35: =IFERROR('Data Sheet'!G29,0) -> 60.7 | G35: =IFERROR('Data Sheet'!H29,0) -> 72.33 | H35: =IFERROR('Data Sheet'!I29,0) -> 108.63 | I35: =IFERROR('Data Sheet'!J29,0) -> 121.35 | J35: =IFERROR('Data Sheet'!K29,0) -> 140.49
B36: Effective Tax Rate % | D36: =D35/D32 -> 0.23172361 | E36: =E35/E32 -> 0.21054373 | F36: =F35/F32 -> 0.24524262 | G36: =G35/G32 -> 0.21420956 | H36: =H35/H32 -> 0.25648714 | I36: =I35/I32 -> 0.24079292 | J36: =J35/J32 -> 0.25062438
B38: Net profit | D38: ='Data Sheet'!E30 -> 120.75 | E38: ='Data Sheet'!F30 -> 235.94 | F38: ='Data Sheet'!G30 -> 184.57 | G38: ='Data Sheet'!H30 -> 266.31 | H38: ='Data Sheet'!I30 -> 313.7 | I38: ='Data Sheet'!J30 -> 380.58 | J38: ='Data Sheet'!K30 -> 417.9
B39: Net profit Margin % | D39: =D38/D11 -> 0.10646177 | E39: =E38/E11 -> 0.1714456 | F39: =F38/F11 -> 0.12380269 | G39: =G38/G11 -> 0.14378503 | H39: =H38/H11 -> 0.14407025 | I39: =I38/I11 -> 0.1451017 | J39: =J38/J11 -> 0.14161589
B41: No. of Equity Shares | D41: =IFERROR('Data Sheet'!E93,0) -> 40.93 | E41: =IFERROR('Data Sheet'!F93,0) -> 40.93 | F41: =IFERROR('Data Sheet'!G93,0) -> 40.93 | G41: =IFERROR('Data Sheet'!H93,0) -> 45.32 | H41: =IFERROR('Data Sheet'!I93,0) -> 45.32 | I41: =IFERROR('Data Sheet'!J93,0) -> 45.32 | J41: =IFERROR('Data Sheet'!K93,0) -> 45.32
B43: EPS | D43: =IFERROR(D38/D41,0) -> 2.9501588 | E43: =IFERROR(E38/E41,0) -> 5.7644759 | F43: =IFERROR(F38/F41,0) -> 4.5094063 | G43: =IFERROR(G38/G41,0) -> 5.8762136 | H43: =IFERROR(H38/H41,0) -> 6.9218888 | I43: =IFERROR(I38/I41,0) -> 8.3976169 | J43: =IFERROR(J38/J41,0) -> 9.2210944
B44: EPS Growth | E44: =IFERROR((E43-D43)/D43,0) -> 0.95395445 | F44: =IFERROR((F43-E43)/E43,0) -> -0.21772485 | G44: =IFERROR((G43-F43)/F43,0) -> 0.30310138 | H44: =IFERROR((H43-G43)/G43,0) -> 0.17795051 | I44: =IFERROR((I43-H43)/H43,0) -> 0.21319732 | J44: =IFERROR((J43-I43)/I43,0) -> 0.098060854
B46: Dividend Per Share | D46: =IFERROR('Data Sheet'!E31/'Data Sheet'!E93,0) -> 0.099926704 | E46: =IFERROR('Data Sheet'!F31/'Data Sheet'!F93,0) -> 0.24993892 | F46: =IFERROR('Data Sheet'!G31/'Data Sheet'!G93,0) -> 0.24993892 | G46: =IFERROR('Data Sheet'!H31/'Data Sheet'!H93,0) -> 0.5 | H46: =IFERROR('Data Sheet'!I31/'Data Sheet'!I93,0) -> 0.59995587 | I46: =IFERROR('Data Sheet'!J31/'Data Sheet'!J93,0) -> 0.80008826 | J46: =IFERROR('Data Sheet'!K31/'Data Sheet'!K93,0) -> 0.90004413
B47: Dividend Payout Ratio | D47: =IFERROR(D46/D43,0) -> 0.033871636 | E47: =IFERROR(E46/E43,0) -> 0.043358481 | F47: =IFERROR(F46/F43,0) -> 0.055426126 | G47: =IFERROR(G46/G43,0) -> 0.085088806 | H47: =IFERROR(H46/H43,0) -> 0.086675167 | I47: =IFERROR(I46/I43,0) -> 0.095275632 | J47: =IFERROR(J46/J43,0) -> 0.097607083
B49: Retained Earnings | D49: =IFERROR(IF(D43>D46,1-D47,0),0) -> 0.96612836 | E49: =IFERROR(IF(E43>E46,1-E47,0),0) -> 0.95664152 | F49: =IFERROR(IF(F43>F46,1-F47,0),0) -> 0.94457387 | G49: =IFERROR(IF(G43>G46,1-G47,0),0) -> 0.91491119 | H49: =IFERROR(IF(H43>H46,1-H47,0),0) -> 0.91332483 | I49: =IFERROR(IF(I43>I46,1-I47,0),0) -> 0.90472437 | J49: =IFERROR(IF(J43>J46,1-J47,0),0) -> 0.90239292
A51: # | B51: Balance Sheet
B53: Equity Share Capital | D53: =IFERROR('Data Sheet'!E57,0) -> 40.93 | E53: =IFERROR('Data Sheet'!F57,0) -> 40.93 | F53: =IFERROR('Data Sheet'!G57,0) -> 40.93 | G53: =IFERROR('Data Sheet'!H57,0) -> 45.32 | H53: =IFERROR('Data Sheet'!I57,0) -> 45.32 | I53: =IFERROR('Data Sheet'!J57,0) -> 45.32 | J53: =IFERROR('Data Sheet'!K57,0) -> 45.32
B54: Reserves | D54: =IFERROR('Data Sheet'!E58,0) -> 595.08 | E54: =IFERROR('Data Sheet'!F58,0) -> 845.56 | F54: =IFERROR('Data Sheet'!G58,0) -> 1161.34 | G54: =IFERROR('Data Sheet'!H58,0) -> 1699.85 | H54: =IFERROR('Data Sheet'!I58,0) -> 2019.74 | I54: =IFERROR('Data Sheet'!J58,0) -> 2421.6 | J54: =IFERROR('Data Sheet'!K58,0) -> 2977.84
B55: Borrowings | D55: =IFERROR('Data Sheet'!E59,0) -> 29.65 | E55: =IFERROR('Data Sheet'!F59,0) -> 34.1 | F55: =IFERROR('Data Sheet'!G59,0) -> 110.78 | G55: =IFERROR('Data Sheet'!H59,0) -> 122.95 | H55: =IFERROR('Data Sheet'!I59,0) -> 244.06 | I55: =IFERROR('Data Sheet'!J59,0) -> 321.91 | J55: =IFERROR('Data Sheet'!K59,0) -> 343.38
B56: Other Liabilities | D56: =IFERROR('Data Sheet'!E60,0) -> 236.37 | E56: =IFERROR('Data Sheet'!F60,0) -> 307.43 | F56: =IFERROR('Data Sheet'!G60,0) -> 323.2 | G56: =IFERROR('Data Sheet'!H60,0) -> 322.27 | H56: =IFERROR('Data Sheet'!I60,0) -> 371.84 | I56: =IFERROR('Data Sheet'!J60,0) -> 450.81 | J56: =IFERROR('Data Sheet'!K60,0) -> 489.27
B57: Total Liabilities | D57: =IFERROR('Data Sheet'!E61,0) -> 902.03 | E57: =IFERROR('Data Sheet'!F61,0) -> 1228.02 | F57: =IFERROR('Data Sheet'!G61,0) -> 1636.25 | G57: =IFERROR('Data Sheet'!H61,0) -> 2190.39 | H57: =IFERROR('Data Sheet'!I61,0) -> 2680.96 | I57: =IFERROR('Data Sheet'!J61,0) -> 3239.64 | J57: =IFERROR('Data Sheet'!K61,0) -> 3855.81
B59: Fixed Assets Net Block | D59: =IFERROR('Data Sheet'!E62,0) -> 302.72 | E59: =IFERROR('Data Sheet'!F62,0) -> 309.36 | F59: =IFERROR('Data Sheet'!G62,0) -> 428.31 | G59: =IFERROR('Data Sheet'!H62,0) -> 486.31 | H59: =IFERROR('Data Sheet'!I62,0) -> 775.94 | I59: =IFERROR('Data Sheet'!J62,0) -> 981.96 | J59: =IFERROR('Data Sheet'!K62,0) -> 1044.11
B60: Capital Work in Progress | D60: =IFERROR('Data Sheet'!E63,0) -> 0 | E60: =IFERROR('Data Sheet'!F63,0) -> 11.68 | F60: =IFERROR('Data Sheet'!G63,0) -> 2.57 | G60: =IFERROR('Data Sheet'!H63,0) -> 9.87 | H60: =IFERROR('Data Sheet'!I63,0) -> 9.42 | I60: =IFERROR('Data Sheet'!J63,0) -> 27.11 | J60: =IFERROR('Data Sheet'!K63,0) -> 58.58
B61: Investments | D61: =IFERROR('Data Sheet'!E64,0) -> 0 | E61: =IFERROR('Data Sheet'!F64,0) -> 0.26 | F61: =IFERROR('Data Sheet'!G64,0) -> 0.44 | G61: =IFERROR('Data Sheet'!H64,0) -> 0.54 | H61: =IFERROR('Data Sheet'!I64,0) -> 26.99 | I61: =IFERROR('Data Sheet'!J64,0) -> 0.74 | J61: =IFERROR('Data Sheet'!K64,0) -> 0
B62: Other Assets | D62: =IFERROR('Data Sheet'!E65-SUM('Data Sheet'!E67:E69),0) -> 20.39 | E62: =IFERROR('Data Sheet'!F65-SUM('Data Sheet'!F67:F69),0) -> 18.27 | F62: =IFERROR('Data Sheet'!G65-SUM('Data Sheet'!G67:G69),0) -> 36.44 | G62: =IFERROR('Data Sheet'!H65-SUM('Data Sheet'!H67:H69),0) -> 77.12 | H62: =IFERROR('Data Sheet'!I65-SUM('Data Sheet'!I67:I69),0) -> 123.91 | I62: =IFERROR('Data Sheet'!J65-SUM('Data Sheet'!J67:J69),0) -> 140.06 | J62: =IFERROR('Data Sheet'!K65-SUM('Data Sheet'!K67:K69),0) -> 146.62
B63: Total Non-Current Assets | D63: =SUM(D59:D62) -> 323.11 | E63: =SUM(E59:E62) -> 339.57 | F63: =SUM(F59:F62) -> 467.76 | G63: =SUM(G59:G62) -> 573.84 | H63: =SUM(H59:H62) -> 936.26 | I63: =SUM(I59:I62) -> 1149.87 | J63: =SUM(J59:J62) -> 1249.31
B65: Receivables | D65: =IFERROR('Data Sheet'!E67,0) -> 243.35 | E65: =IFERROR('Data Sheet'!F67,0) -> 271.95 | F65: =IFERROR('Data Sheet'!G67,0) -> 394.78 | G65: =IFERROR('Data Sheet'!H67,0) -> 416.85 | H65: =IFERROR('Data Sheet'!I67,0) -> 453.18 | I65: =IFERROR('Data Sheet'!J67,0) -> 540.04 | J65: =IFERROR('Data Sheet'!K67,0) -> 644.57
...

Sheet Ratio Analysis
B3: Ratio Analysis of - Marksans Pharma Ltd.
B4: Years | C4: ='Data Sheet'!F16 -> 44286 | D4: ='Data Sheet'!G16 -> 44651 | E4: ='Data Sheet'!H16 -> 45016 | F4: ='Data Sheet'!I16 -> 45382 | G4: ='Data Sheet'!J16 -> 45747 | H4: ='Data Sheet'!K16 -> 46112 | I4: Trend | J4: Mean | K4: Median
B6: Sales Growth | C6: ='Main Financials'!E12 -> 0.21333792 | D6: ='Main Financials'!F12 -> 0.083317589 | E6: ='Main Financials'!G12 -> 0.2423466 | F6: ='Main Financials'!H12 -> 0.17561847 | G6: ='Main Financials'!I12 -> 0.20457332 | H6: ='Main Financials'!J12 -> 0.12508912 | J6: =AVERAGE(C6:H6) -> 0.17404717 | K6: =MEDIAN(C6:H6) -> 0.1900959
B7: EBITDA Growth | C7: =('Main Financials'!E23-'Main Financials'!D23)/'Main Financials'!D23 -> 0.76660598 | D7: =('Main Financials'!F23-'Main Financials'!E23)/'Main Financials'!E23 -> -0.23772929 | E7: =('Main Financials'!G23-'Main Financials'!F23)/'Main Financials'!F23 -> 0.3117154 | F7: =('Main Financials'!H23-'Main Financials'!G23)/'Main Financials'!G23 -> 0.35039312 | G7: =('Main Financials'!I23-'Main Financials'!H23)/'Main Financials'!H23 -> 0.16165118 | H7: =('Main Financials'!J23-'Main Financials'!I23)/'Main Financials'!I23 -> 0.12793077 | J7: =AVERAGE(C7:H7) -> 0.24676119 | K7: =MEDIAN(C7:H7) -> 0.23668329
B8: Net Profit Growth | C8: =('Main Financials'!E38-'Main Financials'!D38)/'Main Financials'!D38 -> 0.95395445 | D8: =('Main Financials'!F38-'Main Financials'!E38)/'Main Financials'!E38 -> -0.21772485 | E8: =('Main Financials'!G38-'Main Financials'!F38)/'Main Financials'!F38 -> 0.4428672 | F8: =('Main Financials'!H38-'Main Financials'!G38)/'Main Financials'!G38 -> 0.17795051 | G8: =('Main Financials'!I38-'Main Financials'!H38)/'Main Financials'!H38 -> 0.21319732 | H8: =('Main Financials'!J38-'Main Financials'!I38)/'Main Financials'!I38 -> 0.098060854 | J8: =AVERAGE(C8:H8) -> 0.27805092 | K8: =MEDIAN(C8:H8) -> 0.19557392
B9: Dividend Growth | C9: =('Main Financials'!E46-'Main Financials'!D46)/'Main Financials'!D46 -> 1.5012225 | D9: =('Main Financials'!F46-'Main Financials'!E46)/'Main Financials'!E46 -> 0 | E9: =('Main Financials'!G46-'Main Financials'!F46)/'Main Financials'!F46 -> 1.0004888 | F9: =('Main Financials'!H46-'Main Financials'!G46)/'Main Financials'!G46 -> 0.19991174 | G9: =('Main Financials'!I46-'Main Financials'!H46)/'Main Financials'!H46 -> 0.33357852 | H9: =('Main Financials'!J46-'Main Financials'!I46)/'Main Financials'!I46 -> 0.12493105 | J9: =AVERAGE(C9:H9) -> 0.52668876 | K9: =MEDIAN(C9:H9) -> 0.26674513
B11: Gross Margin | C11: ='Main Financials'!E18 -> 0.38755831 | D11: ='Main Financials'!F18 -> 0.35040648 | E11: ='Main Financials'!G18 -> 0.34995735 | F11: ='Main Financials'!H18 -> 0.33131565 | G11: ='Main Financials'!I18 -> 0.36168671 | H11: ='Main Financials'!J18 -> 0.35336876 | J11: =AVERAGE(C11:H11) -> 0.35571554 | K11: =MEDIAN(C11:H11) -> 0.35188762
B12: EBITDA Margin | C12: ='Main Financials'!E24 -> 0.24679184 | D12: ='Main Financials'!F24 -> 0.17365378 | E12: ='Main Financials'!G24 -> 0.18335007 | F12: ='Main Financials'!H24 -> 0.21060802 | G12: ='Main Financials'!I24 -> 0.20310349 | H12: ='Main Financials'!J24 -> 0.20361647 | J12: =AVERAGE(C12:H12) -> 0.20352061 | K12: =MEDIAN(C12:H12) -> 0.20335998
B13: EBIT Margin | C13: =('Main Financials'!E23-'Main Financials'!E29)/'Main Financials'!E11 -> 0.22052348 | D13: =('Main Financials'!F23-'Main Financials'!F29)/'Main Financials'!F11 -> 0.14361702 | E13: =('Main Financials'!G23-'Main Financials'!G29)/'Main Financials'!G11 -> 0.15535543 | F13: =('Main Financials'!H23-'Main Financials'!H29)/'Main Financials'!H11 -> 0.17649868 | G13: =('Main Financials'!I23-'Main Financials'!I29)/'Main Financials'!I11 -> 0.17130983 | H13: =('Main Financials'!J23-'Main Financials'!J29)/'Main Financials'!J11 -> 0.17019323 | J13: =AVERAGE(C13:H13) -> 0.17291628 | K13: =MEDIAN(C13:H13) -> 0.17075153
B14: EBT Margin | C14: ='Main Financials'!E33 -> 0.21957157 | D14: ='Main Financials'!F33 -> 0.1660205 | E14: ='Main Financials'!G33 -> 0.18230803 | F14: ='Main Financials'!H33 -> 0.19451091 | G14: ='Main Financials'!I33 -> 0.19214214 | H14: ='Main Financials'!J33 -> 0.18995981 | J14: =AVERAGE(C14:H14) -> 0.19075216 | K14: =MEDIAN(C14:H14) -> 0.19105097
B15: Net Profit Margin | C15: ='Main Financials'!E39 -> 0.1714456 | D15: ='Main Financials'!F39 -> 0.12380269 | E15: ='Main Financials'!G39 -> 0.14378503 | F15: ='Main Financials'!H39 -> 0.14407025 | G15: ='Main Financials'!I39 -> 0.1451017 | H15: ='Main Financials'!J39 -> 0.14161589 | J15: =AVERAGE(C15:H15) -> 0.14497019 | K15: =MEDIAN(C15:H15) -> 0.14392764
B17: SalesExpenses%Sales | C17: ='Main Financials'!E21 -> 0.14076647 | D17: ='Main Financials'!F21 -> 0.1767527 | E17: ='Main Financials'!G21 -> 0.16660728 | F17: ='Main Financials'!H21 -> 0.12070763 | G17: ='Main Financials'!I21 -> 0.15858322 | H17: ='Main Financials'!J21 -> 0.14975228 | J17: =AVERAGE(C17:H17) -> 0.15219493 | K17: =MEDIAN(C17:H17) -> 0.15416775
B18: Depreciation%Sales | C18: ='Main Financials'!E30 -> 0.026268366 | D18: ='Main Financials'!F30 -> 0.030036758 | E18: ='Main Financials'!G30 -> 0.027994644 | F18: ='Main Financials'!H30 -> 0.034109332 | G18: ='Main Financials'!I30 -> 0.03179366 | H18: ='Main Financials'!J30 -> 0.033423248 | J18: =AVERAGE(C18:H18) -> 0.030604335 | K18: =MEDIAN(C18:H18) -> 0.030915209
B19: OperatingIncome%Sales | C19: =C13 -> 0.22052348 | D19: =D13 -> 0.14361702 | E19: =E13 -> 0.15535543 | F19: =F13 -> 0.17649868 | G19: =G13 -> 0.17130983 | H19: =H13 -> 0.17019323 | J19: =AVERAGE(C19:H19) -> 0.17291628 | K19: =MEDIAN(C19:H19) -> 0.17075153
B21: Return on Capital Employed | C21: =('Main Financials'!E23-'Main Financials'!E29)/(SUM('Main Financials'!E53:E54)+'Main Financials'!E55) -> 0.32965815 | D21: =('Main Financials'!F23-'Main Financials'!F29)/(SUM('Main Financials'!F53:F54)+'Main Financials'!F55) -> 0.1630631 | E21: =('Main Financials'!G23-'Main Financials'!G29)/(SUM('Main Financials'!G53:G54)+'Main Financials'!G55) -> 0.15402651 | F21: =('Main Financials'!H23-'Main Financials'!H29)/(SUM('Main Financials'!H53:H54)+'Main Financials'!H55) -> 0.16643137 | G21: =('Main Financials'!I23-'Main Financials'!I29)/(SUM('Main Financials'!I53:I54)+'Main Financials'!I55) -> 0.16111416 | H21: =('Main Financials'!J23-'Main Financials'!J29)/(SUM('Main Financials'!J53:J54)+'Main Financials'!J55) -> 0.14918284 | J21: =AVERAGE(C21:H21) -> 0.18724602 | K21: =MEDIAN(C21:H21) -> 0.16208863
B22: Retained Earnings% | C22: ='Main Financials'!E49 -> 0.95664152 | D22: ='Main Financials'!F49 -> 0.94457387 | E22: ='Main Financials'!G49 -> 0.91491119 | F22: ='Main Financials'!H49 -> 0.91332483 | G22: ='Main Financials'!I49 -> 0.90472437 | H22: ='Main Financials'!J49 -> 0.90239292 | J22: =AVERAGE(C22:H22) -> 0.92276145 | K22: =MEDIAN(C22:H22) -> 0.91411801
B23: Return on Equity% | C23: ='Main Financials'!E38/(SUM('Main Financials'!E53:E54)) -> 0.26615077 | D23: ='Main Financials'!F38/(SUM('Main Financials'!F53:F54)) -> 0.15351793 | E23: ='Main Financials'!G38/(SUM('Main Financials'!G53:G54)) -> 0.15259831 | F23: ='Main Financials'!H38/(SUM('Main Financials'!H53:H54)) -> 0.15190842 | G23: ='Main Financials'!I38/(SUM('Main Financials'!I53:I54)) -> 0.15427334 | H23: ='Main Financials'!J38/(SUM('Main Financials'!J53:J54)) -> 0.13823284 | J23: =AVERAGE(C23:H23) -> 0.16944694 | K23: =MEDIAN(C23:H23) -> 0.15305812
B24: Self Sustained Growth Rate | C24: =C22*C23 -> 0.25461088 | D24: =D22*D23 -> 0.14500902 | E24: =E22*E23 -> 0.13961391 | F24: =F22*F23 -> 0.13874173 | G24: =G22*G23 -> 0.13957485 | H24: =H22*H23 -> 0.12474034 | J24: =AVERAGE(C24:H24) -> 0.15704846 | K24: =MEDIAN(C24:H24) -> 0.13959438
B26: Debtor Turnover Ratio | C26: ='Main Financials'!E11/'Main Financials'!E65 -> 5.0604155 | D26: ='Main Financials'!F11/'Main Financials'!F65 -> 3.7763818 | E26: ='Main Financials'!G11/'Main Financials'!G65 -> 4.443181 | F26: ='Main Financials'!H11/'Main Financials'!H65 -> 4.8047354 | G26: ='Main Financials'!I11/'Main Financials'!I65 -> 4.8567699 | H26: ='Main Financials'!J11/'Main Financials'!J65 -> 4.5781529 | J26: =AVERAGE(C26:H26) -> 4.5866061 | K26: =MEDIAN(C26:H26) -> 4.6914442
B27: Fixed Asset Turnover | C27: ='Main Financials'!E11/'Main Financials'!E59 -> 4.4484743 | D27: ='Main Financials'!F11/'Main Financials'!F59 -> 3.4807499 | E27: ='Main Financials'!G11/'Main Financials'!G59 -> 3.8085583 | F27: ='Main Financials'!H11/'Main Financials'!H59 -> 2.8061577 | G27: ='Main Financials'!I11/'Main Financials'!I59 -> 2.6710355 | H27: ='Main Financials'!J11/'Main Financials'!J59 -> 2.8262731 | J27: =AVERAGE(C27:H27) -> 3.3402081 | K27: =MEDIAN(C27:H27) -> 3.1535115
B28: Capital Turnover Ratio | C28: ='Main Financials'!E11/SUM('Main Financials'!E53:E54) -> 1.552392 | D28: ='Main Financials'!F11/SUM('Main Financials'!F53:F54) -> 1.240021 | E28: ='Main Financials'!G11/SUM('Main Financials'!G53:G54) -> 1.0612949 | F28: ='Main Financials'!H11/SUM('Main Financials'!H53:H54) -> 1.0544052 | G28: ='Main Financials'!I11/SUM('Main Financials'!I53:I54) -> 1.0632084 | H28: ='Main Financials'!J11/SUM('Main Financials'!J53:J54) -> 0.97611109 | J28: =AVERAGE(C28:H28) -> 1.1579054 | K28: =MEDIAN(C28:H28) -> 1.0622516
B30: Debtor Days | C30: =365/C26 -> 72.128464 | D30: =365/D26 -> 96.653363 | E30: =365/E26 -> 82.148353 | F30: =365/F26 -> 75.966722 | G30: =365/G26 -> 75.15283 | H30: =365/H26 -> 79.726477 | J30: =AVERAGE(C30:H30) -> 80.296035 | K30: =MEDIAN(C30:H30) -> 77.846599
B32: CFO/Sales | C32: ='Main Financials'!E85/'Main Financials'!E11 -> 0.13007019 | D32: ='Main Financials'!F85/'Main Financials'!F11 -> 0.066405516 | E32: ='Main Financials'!G85/'Main Financials'!G11 -> 0.12796009 | F32: ='Main Financials'!H85/'Main Financials'!H11 -> 0.10563008 | G32: ='Main Financials'!I85/'Main Financials'!I11 -> 0.078921784 | H32: ='Main Financials'!J85/'Main Financials'!J11 -> 0.15520478 | J32: =AVERAGE(C32:H32) -> 0.11069874 | K32: =MEDIAN(C32:H32) -> 0.11679509
B33: CFO/Total Assets | C33: ='Main Financials'!E85/'Main Financials'!E70 -> 0.1457631 | D33: ='Main Financials'!F85/'Main Financials'!F70 -> 0.060504202 | E33: ='Main Financials'!G85/'Main Financials'!G70 -> 0.10819991 | F33: ='Main Financials'!H85/'Main Financials'!H70 -> 0.085790165 | G33: ='Main Financials'!I85/'Main Financials'!I70 -> 0.063895988 | H33: ='Main Financials'!J85/'Main Financials'!J70 -> 0.11878179 | J33: =AVERAGE(C33:H33) -> 0.097155858 | K33: =MEDIAN(C33:H33) -> 0.096995037
B34: CFO/Total Debt | C34: ='Main Financials'!E85/'Main Financials'!E55 -> 5.2492669 | D34: ='Main Financials'!F85/'Main Financials'!F55 -> 0.89366312 | E34: ='Main Financials'!G85/'Main Financials'!G55 -> 1.9276129 | F34: ='Main Financials'!H85/'Main Financials'!H55 -> 0.94239122 | G34: ='Main Financials'!I85/'Main Financials'!I55 -> 0.64303687 | H34: ='Main Financials'!J85/'Main Financials'!J55 -> 1.3337993 | J34: =AVERAGE(C34:H34) -> 1.8316284 | K34: =MEDIAN(C34:H34) -> 1.1380953

Sheet Intrinsic Growth
B4: Calculation of ROIC | E4: =BS!J2 -> 44621 | F4: =BS!K2 -> 44986 | G4: =BS!L2 -> 45352 | H4: =BS!M2 -> 45717 | I4: =BS!N2 -> 46082
B6: Current Assets
B7: =BS!B33 -> Inventories | E7: =BS!J33 -> 424 | F7: =BS!K33 -> 485 | G7: =BS!L33 -> 618 | H7: =BS!M33 -> 846 | I7: =BS!N33 -> 972
B8: =BS!B34 -> Trade receivables | E8: =BS!J34 -> 395 | F8: =BS!K34 -> 417 | G8: =BS!L34 -> 453 | H8: =BS!M34 -> 540 | I8: =BS!N34 -> 645
B9: =BS!B36 -> Loans n Advances | E9: =BS!J36 -> 21 | F9: =BS!K36 -> 29 | G9: =BS!L36 -> 38 | H9: =BS!M36 -> 55 | I9: =BS!N36 -> 65
B10: =BS!B37 -> Other asset items | E10: =BS!J37 -> 15 | F10: =BS!K37 -> 48 | G10: =BS!L37 -> 86 | H10: =BS!M37 -> 85 | I10: =BS!N37 -> 81
B11: Total Current Assets | E11: =SUM(E7:E10) -> 855 | F11: =SUM(F7:F10) -> 979 | G11: =SUM(G7:G10) -> 1195 | H11: =SUM(H7:H10) -> 1526 | I11: =SUM(I7:I10) -> 1763
B13: Current Liabilities
B14: =BS!B13 -> Trade Payables | E14: =BS!J13 -> 200 | F14: =BS!K13 -> 231 | G14: =BS!L13 -> 268 | H14: =BS!M13 -> 306 | I14: =BS!N13 -> 337
B15: =BS!B14 -> Advance from Customers | E15: =BS!J14 -> 2 | F15: =BS!K14 -> 1 | G15: =BS!L14 -> 2 | H15: =BS!M14 -> 1 | I15: =BS!N14 -> 2
B16: =BS!B15 -> Other liability items | E16: =BS!J15 -> 101 | F16: =BS!K15 -> 71 | G16: =BS!L15 -> 81 | H16: =BS!M15 -> 121 | I16: =BS!N15 -> 121
B17: Total Current Liabilities | E17: =SUM(E14:E16) -> 303 | F17: =SUM(F14:F16) -> 303 | G17: =SUM(G14:G16) -> 351 | H17: =SUM(H14:H16) -> 428 | I17: =SUM(I14:I16) -> 460
B19: Net Working Capital | E19: =E11-E17 -> 552 | F19: =F11-F17 -> 676 | G19: =G11-G17 -> 844 | H19: =H11-H17 -> 1098 | I19: =I11-I17 -> 1303
B21: Non Current Assets
B22: Land | E22: =BS!J19 -> 1 | F22: =BS!K19 -> 1 | G22: =BS!L19 -> 23 | H22: =BS!M19 -> 23 | I22: =BS!N19 -> 23
B23: Building | E23: =BS!J20 -> 226 | F23: =BS!K20 -> 270 | G23: =BS!L20 -> 483 | H23: =BS!M20 -> 625 | I23: =BS!N20 -> 692
B24: Plant Machinery | E24: =BS!J21 -> 287 | F24: =BS!K21 -> 307 | G24: =BS!L21 -> 421 | H24: =BS!M21 -> 531 | I24: =BS!N21 -> 604
B25: =BS!B23 -> Computers | E25: =BS!J23 -> 7 | F25: =BS!K23 -> 7 | G25: =BS!L23 -> 12 | H25: =BS!M23 -> 13 | I25: =BS!N23 -> 16
B26: Equipments | E26: =BS!J22 -> 4 | F26: =BS!K22 -> 5 | G26: =BS!L22 -> 5 | H26: =BS!M22 -> 5 | I26: =BS!N22 -> 6
B27: Furniture n fittings | E27: =BS!J24 -> 11 | F27: =BS!K24 -> 16 | G27: =BS!L24 -> 21 | H27: =BS!M24 -> 29 | I27: =BS!N24 -> 33
B28: Vehicles | E28: =BS!J25 -> 10 | F28: =BS!K25 -> 10 | G28: =BS!L25 -> 11 | H28: =BS!M25 -> 11 | I28: =BS!N25 -> 16
B29: Intangible Assets | E29: =BS!J26 -> 30 | F29: =BS!K26 -> 38 | G29: =BS!L26 -> 60 | H29: =BS!M26 -> 61 | I29: =BS!N26 -> 68
B30: Other fixed assets | E30: =BS!J27 -> 150 | F30: =BS!K27 -> 174 | G30: =BS!L27 -> 158 | H30: =BS!M27 -> 114 | I30: =BS!N27 -> 148
B32: Gross Block | E32: =SUM(E22:E31) -> 726 | F32: =SUM(F22:F31) -> 828 | G32: =SUM(G22:G31) -> 1194 | H32: =SUM(H22:H31) -> 1412 | I32: =SUM(I22:I31) -> 1606
B33: Accumulated Depreciation | E33: =BS!J29 -> 298 | F33: =BS!K29 -> 342 | G33: =BS!L29 -> 418 | H33: =BS!M29 -> 431 | I33: =BS!N29 -> 561
B34: Net Non Current Assets | E34: =E32-E33 -> 428 | F34: =F32-F33 -> 486 | G34: =G32-G33 -> 776 | H34: =H32-H33 -> 981 | I34: =I32-I33 -> 1045
B36: Invested Capital | E36: =E34+E19 -> 980 | F36: =F34+F19 -> 1162 | G36: =G34+G19 -> 1620 | H36: =H34+H19 -> 2079 | I36: =I34+I19 -> 2348
B37: EBIT | E37: =('Main Financials'!F23-'Main Financials'!F29) -> 214.11 | F37: =('Main Financials'!G23-'Main Financials'!G29) -> 287.74 | G37: =('Main Financials'!H23-'Main Financials'!H29) -> 384.31 | H37: =('Main Financials'!I23-'Main Financials'!I29) -> 449.32 | I37: =('Main Financials'!J23-'Main Financials'!J29) -> 502.23
B39: ROIC | E39: =E48/E36 -> 0.15293571 | F39: =F48/F36 -> 0.17333735 | G39: =G48/G36 -> 0.16605988 | H39: =H48/H36 -> 0.1512862 | I39: =I48/I36 -> 0.14972785
B41: Calculation of Reinvestment Rate | E41: 44621 | F41: 44986 | G41: 45352 | H41: 45717 | I41: 46082
B43: Net Capex | E43: =-('Cash Flow'!J15+'Cash Flow'!J16)-'Main Financials'!F29 -> 1.22 | F43: =-('Cash Flow'!K15+'Cash Flow'!K16)-'Main Financials'!G29 -> 2.15 | G43: =-('Cash Flow'!L15+'Cash Flow'!L16)-'Main Financials'!H29 -> 133.73 | H43: =-('Cash Flow'!M15+'Cash Flow'!M16)-'Main Financials'!I29 -> 88.61 | I43: =-('Cash Flow'!N15+'Cash Flow'!N16)-'Main Financials'!J29 -> 31.37
B44: Change in Working Capital | F44: =F19-E19 -> 124 | G44: =G19-F19 -> 168 | H44: =H19-G19 -> 254 | I44: =I19-H19 -> 205
B46: EBIT | E46: =E37 -> 214.11 | F46: =F37 -> 287.74 | G46: =G37 -> 384.31 | H46: =H37 -> 449.32 | I46: =I37 -> 502.23
B47: Marginal Tax Rate | E47: 0.3 | F47: 0.3 | G47: 0.3 | H47: 0.3 | I47: 0.3
B48: EBIT(1-T) | E48: =E46*(1-E47) -> 149.877 | F48: =F46*(1-F47) -> 201.418 | G48: =G46*(1-G47) -> 269.017 | H48: =H46*(1-H47) -> 314.524 | I48: =I46*(1-I47) -> 351.561
B50: Reinvestment | F50: =F43+F44 -> 126.15 | G50: =G43+G44 -> 301.73 | H50: =H43+H44 -> 342.61 | I50: =I43+I44 -> 236.37
B52: Reinvestment Rate | F52: =F50/F48 -> 0.62630947 | G52: =G50/G48 -> 1.121602 | H52: =H50/H48 -> 1.0892968 | I52: =I50/I48 -> 0.6723442
H54: 4 Year Average | I54: =AVERAGE(F52:I52) -> 0.87738812
H55: 4 Year Median | I55: =MEDIAN(F52:I52) -> 0.88082052
B57: Calculation of Growth Rate | E57: 44621 | F57: 44986 | G57: 45352 | H57: 45717 | I57: 46082
...

Sheet Comps
B3: Amount in crores
B4: Comparable Company Valuation
D6: Market Data | J6: Financials | N6: Valuation
B7: Company | C7: Ticker | D7: Share Price | E7: Shares Outstanding | F7: Equity Value | G7: Net Debt | H7: Enterprise Value | J7: Revenue | K7: EBITDA | L7: Net Income | N7: EV/Revenue | O7: EV/EBITDA | P7: P/E
B8: =compdata!C10 -> Marksans Pharma | D8: =compdata!D10 -> 309.1 | E8: =compdata!E10 -> 45.32 | F8: =compdata!F10 -> 14008.412 | G8: =compdata!I10 -> -646.27 | H8: =compdata!J10 -> 13362.142 | J8: =compdata!L10 -> 3171.75 | K8: =compdata!K10 -> 816.25791 | L8: =compdata!M10 -> 521.27 | N8: =H8/J8 -> 4.212861 | O8: =H8/K8 -> 16.37 | P8: =F8/L8 -> 26.87362
B9: =compdata!C3 -> Sun Pharma.Inds. | D9: =compdata!D3 -> 1760 | E9: =compdata!E3 -> 239.93 | F9: =E9*D9 -> 422276.8 | G9: =compdata!I3 -> -6975.76 | H9: =compdata!J3 -> 415301.04 | J9: =compdata!L3 -> 59910.52 | K9: =compdata!K3 -> 20082.255 | L9: =compdata!M3 -> 12117.01 | N9: =H9/J9 -> 6.932022 | O9: =H9/K9 -> 20.68 | P9: =F9/L9 -> 34.849918
B10: =compdata!C4 -> Divi's Lab. | D10: =compdata!D4 -> 9340 | E10: =compdata!E4 -> 26.55 | F10: =E10*D10 -> 247977 | G10: =compdata!I4 -> -3407 | H10: =compdata!J4 -> 244570 | J10: =compdata!L4 -> 11230 | K10: =compdata!K4 -> 4419.4073 | L10: =compdata!M4 -> 2925 | N10: =H10/J10 -> 21.778272 | O10: =H10/K10 -> 55.34 | P10: =F10/L10 -> 84.778462
B11: =compdata!C5 -> Torrent Pharma. | D11: =compdata!D5 -> 4656.9 | E11: =compdata!E5 -> 38.04 | F11: =E11*D11 -> 177148.48 | G11: =compdata!I5 -> 13860.3 | H11: =compdata!J5 -> 191008.78 | J11: =compdata!L5 -> 15723 | K11: =compdata!K5 -> 5122.252 | L11: =compdata!M5 -> 2156 | N11: =H11/J11 -> 12.148367 | O11: =H11/K11 -> 37.29 | P11: =F11/L11 -> 82.165341
B12: =compdata!C6 -> Zydus Lifesci. | D12: =compdata!D6 -> 1117.5 | E12: =compdata!E6 -> 99.75 | F12: =E12*D12 -> 111470.62 | G12: =compdata!I6 -> 11079.4 | H12: =compdata!J6 -> 122550.02 | J12: =compdata!L6 -> 28591.7 | K12: =compdata!K6 -> 8778.6551 | L12: =compdata!M6 -> 4592.7 | N12: =H12/J12 -> 4.2862098 | O12: =H12/K12 -> 13.96 | P12: =F12/L12 -> 24.271262
B13: =compdata!C7 -> Laurus Labs | D13: =compdata!D7 -> 2036.6 | E13: =compdata!E7 -> 54.03 | F13: =E13*D13 -> 110037.5 | G13: =compdata!I7 -> 2404.78 | H13: =compdata!J7 -> 112442.28 | J13: =compdata!L7 -> 7269.64 | K13: =compdata!K7 -> 2087.6769 | L13: =compdata!M7 -> 1090.53 | N13: =H13/J13 -> 15.467379 | O13: =H13/K13 -> 53.86 | P13: =F13/L13 -> 100.90277
B14: =compdata!C8 -> Cipla | D14: =compdata!D8 -> 1301 | E14: =compdata!E8 -> 80.79 | F14: =E14*D14 -> 105107.79 | G14: =compdata!I8 -> -693.65 | H14: =compdata!J8 -> 104414.14 | J14: =compdata!L8 -> 28324.4 | K14: =compdata!K8 -> 6131.1885 | L14: =compdata!M8 -> 3355.68 | N14: =H14/J14 -> 3.6863672 | O14: =H14/K14 -> 17.03 | P14: =F14/L14 -> 31.322352
B15: =compdata!C9 -> Dr Reddy's Labs | D15: =compdata!D9 -> 1197 | E15: =compdata!E9 -> 83.47 | F15: =E15*D15 -> 99913.59 | G15: =compdata!I9 -> 4385.4 | H15: =compdata!J9 -> 104298.99 | J15: =compdata!L9 -> 33227.9 | K15: =compdata!K9 -> 6576.2289 | L15: =compdata!M9 -> 3183.3 | N15: =H15/J15 -> 3.138898 | O15: =H15/K15 -> 15.86 | P15: =F15/L15 -> 31.386797
B17: High | N17: =MAX(N8:N15) -> 21.778272 | O17: =MAX(O8:O15) -> 55.34 | P17: =MAX(P8:P15) -> 100.90277
B18: 75th Percentile | N18: =QUARTILE(N8:N15,3) -> 12.97812 | O18: =QUARTILE(O8:O15,3) -> 41.4325 | P18: =QUARTILE(P8:P15,3) -> 82.818621
B19: Average | N19: =AVERAGE(N8:N15) -> 8.9562971 | O19: =AVERAGE(O8:O15) -> 28.79875 | P19: =AVERAGE(P8:P15) -> 52.068815
B20: Median | N20: =MEDIAN(N8:N15) -> 5.6091159 | O20: =MEDIAN(O8:O15) -> 18.855 | P20: =MEDIAN(P8:P15) -> 33.118357
B21: 25th Percentile | N21: =QUARTILE(N8:N15,1) -> 4.0812376 | O21: =QUARTILE(O8:O15,1) -> 16.2425 | P21: =QUARTILE(P8:P15,1) -> 30.210169
B22: Low | N22: =MIN(N8:N15) -> 3.138898 | O22: =MIN(O8:O15) -> 13.96 | P22: =MIN(P8:P15) -> 24.271262
B24: Marksans Pharma Comparable Valuation | N24: EV/Revenue | O24: EV/EBITDA | P24: P/E
B26: Implied Enterprise Value | N26: =N20*J8 -> 17790.713 | O26: =O20*K8 -> 15390.543 | P26: =P27+P28 -> 16617.336
B27: Net Debt | N27: =$G$8 -> -646.27 | O27: =$G$8 -> -646.27 | P27: =O27 -> -646.27
B28: Implied Market Value | N28: =N26-N27 -> 18436.983 | O28: =O26-O27 -> 16036.813 | P28: =P20*L8 -> 17263.606
B29: Shares Outstanding | N29: =$E$8 -> 45.32 | O29: =$E$8 -> 45.32 | P29: =$E$8 -> 45.32
B31: Implied Value per Share | N31: =N28/N29 -> 406.81781 | O31: =O28/O29 -> 353.8573 | P31: =P28/P29 -> 380.92688
N34: {=_xlfn.IFS(N$31>$D$8,"undervalued",N$31<$D$8,"overvalued",N$31=N$31,"Fair Value")} -> undervalued | O34: {=_xlfn.IFS(O$31>$D$8,"undervalued",O$31<$D$8,"overvalued",O$31=O$31,"Fair Value")} -> undervalued | P34: {=_xlfn.IFS(P$31>$D$8,"undervalued",P$31<$D$8,"overvalued",P$31=P$31,"Fair Value")} -> undervalued

Sheet WACC-DCF
B3: Weighted Average Cost of Capital
B5: All figures are in INR unless stated otherwise.
B7: Peer Comps
G8: Debt/ | H8: Debt/ | I8: Levered | J8: Unlevered
B9: Name | C9: Country | D9: Total Debt | E9: Total Equity | F9: Tax Rate 1 | G9: Equity | H9: Capital | I9: Beta | J9: Beta | P9: (Trading Economics)
P10: (Yahoo Finance / NSE website) | T10: year returns - company + nse
B11: Sun Pharma.Inds. | C11: India | D11: =peerdata!G5 -> 4627.32 | E11: =peerdata!E5 -> 424041.97 | F11: 0.3 | G11: =D11/E11 -> 0.01091241 | H11: =D11/(D11+E11) -> 0.010794615 | I11: 0.542 | J11: =I11/(1+(1-F11)*G11) -> 0.53789122 | P11: ( top stock research) | T11: beta
B12: Divi's Lab. | C12: India | D12: =peerdata!G6 -> 7 | E12: =peerdata!E6 -> 247208.22 | F12: 0.3 | G12: =D12/E12 -> 2.8316211e-05 | H12: =D12/(D12+E12) -> 2.8315409e-05 | I12: 0.901 | J12: =I12/(1+(1-F12)*G12) -> 0.90098214 | P12: (investing.com) | T12: risk free rate
B13: Torrent Pharma. | C13: India | D13: =peerdata!G7 -> 15025.5 | E13: =peerdata!E7 -> 174939.7 | F13: 0.3 | G13: =D13/E13 -> 0.085889595 | H13: =D13/(D13+E13) -> 0.079096066 | I13: 0.49 | J13: =I13/(1+(1-F13)*G13) -> 0.46221064 | P13: (prime investor.in) | T13: div yeild nse
B14: Zydus Lifesci. | C14: India | D14: =peerdata!G8 -> 12496 | E14: =peerdata!E8 -> 111151.2 | F14: 0.3 | G14: =D14/E14 -> 0.11242344 | H14: =D14/(D14+E14) -> 0.10106173 | I14: 0.513 | J14: =I14/(1+(1-F14)*G14) -> 0.47557403
B15: Laurus Labs | C15: India | D15: =peerdata!G9 -> 2518.48 | E15: =peerdata!E9 -> 109924.45 | F15: 0.3 | G15: =D15/E15 -> 0.022911008 | H15: =D15/(D15+E15) -> 0.022397851 | I15: 1.07 | J15: =I15/(1+(1-F15)*G15) -> 1.0531105
E17: Average | F17: =AVERAGE(F11:F15) -> 0.3 | G17: =AVERAGE(G11:G15) -> 0.046432954 | H17: =AVERAGE(H11:H15) -> 0.042675716 | I17: =AVERAGE(I11:I15) -> 0.7032 | J17: =AVERAGE(J11:J15) -> 0.68595371
E18: Median | F18: =MEDIAN(F11:F15) -> 0.3 | G18: =MEDIAN(G11:G15) -> 0.022911008 | H18: =MEDIAN(H11:H15) -> 0.022397851 | I18: =MEDIAN(I11:I15) -> 0.542 | J18: =MEDIAN(J11:J15) -> 0.53789122
B20: Cost of Debt | G20: Cost of Equity
B22: Pre-tax Cost of Debt | E22: 0.08 | G22: Risk Free Rate | J22: 0.073 | K22: (Latest)
B23: Tax Rate | E23: =F18 -> 0.3 | G23: Equity Risk Premium | J23: =RM!F12-J22 -> 0.090692308
B24: After Tax Cost of Debt | E24: =E22*(1-E23) -> 0.056 | G24: Levered Beta 4 | J24: =J32 -> 0.54651776
G25: Cost of Equity | J25: =J22+J24*(J23) -> 0.12256496
B27: Capital Structure | G27: Levered Beta
D29: Current | E29: Target | G29: Comps Median Unlevered Beta | J29: =J18 -> 0.53789122
B30: Total Debt | C30: 343.38 | D30: =C30/$C$32 -> 0.023935392 | E30: =H18 -> 0.022397851 | G30: Target Debt/ Equity | J30: =E34 -> 0.022911008
B31: Market Capitalization | C31: 14002.74 | D31: =1-D30 -> 0.97606461 | E31: =E32-E30 -> 0.97760215 | G31: Tax Rate | J31: =E23 -> 0.3
B32: Total Capitalization | C32: =SUM(C30:C31) -> 14346.12 | D32: =C32/$C$32 -> 1 | E32: =D32 -> 1 | G32: Levered Beta | J32: =J29*(1+(1-J31)*J30) -> 0.54651776
B34: Debt / Equity | D34: =D30/D31 -> 0.024522343 | E34: =E30/E31 -> 0.022911008 | G34: Weighted Average Cost of Capital
B36: 1. Tax Rate considered as Marginal Tax Rate for the country | I36: Total Cost | J36: Total Weight
B37: 2. Levered Beta is based on 5 year monthly data | G37: Debt Capital | I37: =E24 -> 0.056 | J37: =E30 -> 0.022397851
B38: 3. Unlevered Beta = Levered Beta/(1+(1-Tax Rate) x Debt/Equity) | G38: Equity Capital | I38: =J25 -> 0.12256496 | J38: =E31 -> 0.97760215
B39: 4. Levered Beta = Unlevered Beta*(1+(1-Tax Rate) x Debt/Equity) | G39: Weighted Average Cost of Capital | J39: =SUMPRODUCT(I37:I38,J37:J38) -> 0.12107404

Sheet DCF 1st way
F2: 0 | G2: 0.5 | H2: 1.5 | I2: 2.5 | J2: 3.5 | K2: 4.5
B3: Calculation of PV of FCFF | F3: ='Intrinsic Growth'!I41 -> 46082 | G3: =F3+365 -> 46447 | H3: =G3+366 -> 46813 | I3: =H3+365 -> 47178 | J3: =I3+365 -> 47543 | K3: =J3+365 -> 47908
B5: EBIT | F5: ='Intrinsic Growth'!I46 -> 502.23 | G5: =F5*(1+$E$19) -> 577.5645 | H5: =G5*(1+$E$19) -> 664.19918 | I5: =H5*(1+$E$19) -> 763.82905 | J5: =I5*(1+$E$19) -> 878.40341 | K5: =J5*(1+$E$19) -> 1010.1639
B7: Tax Rate | F7: 0.3 | G7: 0.3 | H7: 0.3 | I7: 0.3 | J7: 0.3 | K7: 0.3
B9: EBIT (1-T) | F9: =F5*(1-F7) -> 351.561 | G9: =G5*(1-G7) -> 404.29515 | H9: =H5*(1-H7) -> 464.93942 | I9: =I5*(1-I7) -> 534.68034 | J9: =J5*(1-J7) -> 614.88239 | K9: =K5*(1-K7) -> 707.11474
B11: Less: Reinvestment Rate | F11: 0.6395 | G11: 0.6395 | H11: 0.6395 | I11: 0.6395 | J11: 0.6395 | K11: 0.6395
B13: Free Cash Flow to Firm | F13: =F9*(1-F11) -> 126.73774 | G13: =G9*(1-G11) -> 145.7484 | H13: =H9*(1-H11) -> 167.61066 | I13: =I9*(1-I11) -> 192.75226 | J13: =J9*(1-J11) -> 221.6651 | K13: =K9*(1-K11) -> 254.91487
B15: Discounting Factor | F15: =1/(1+$E$26)^F2 -> 1 | G15: =1/(1+$E$26)^G2 -> 0.94445844 | H15: =1/(1+$E$26)^H2 -> 0.84245857 | I15: =1/(1+$E$26)^I2 -> 0.75147451 | J15: =1/(1+$E$26)^J2 -> 0.67031657 | K15: =1/(1+$E$26)^K2 -> 0.59792355
B17: PV of FCFF | F17: =F13*F15 -> 126.73774 | G17: =G13*G15 -> 137.65331 | H17: =H13*H15 -> 141.20504 | I17: =I13*I15 -> 144.84841 | J17: =J13*J15 -> 148.58579 | K17: =K13*K15 -> 152.4196
B19: Expected Growth | E19: 0.15
B20: Terminal Growth | E20: 0.05
B23: Calculation of Terminal Value | G23: Sensivity Analysis | H23: Sensitivity Analysis
G24: =E36 -> 2976.4565 | H24: 0.03 | I24: 0.04 | J24: 0.05 | K24: 0.06
B25: FCFF (n+1) | E25: =K13*(1+E27) -> 267.66061 | G25: 0.1 | H25: 3203.6153 | I25: 3638.3973 | J25: 4247.0919 | K25: 5160.134
B26: WACC | E26: ='WACC-DCF'!J39 -> 0.12107404 | G26: 0.11 | H26: 2795.427 | I26: 3111.3467 | J26: 3532.5729 | K26: 4122.2897
B27: Terminal Growth Rate | E27: =E20 -> 0.05 | G27: 0.12107404 | H27: 2448.4984 | I27: 2679.9172 | J27: 2976.4565 | K27: 3370.104
G28: 0.13 | H28: 2225.1272 | I28: 2409.7894 | J28: 2640.6172 | K28: 2937.3958
B29: Terminal Value | E29: =E25/(E26-E27) -> 3765.9403 | G29: 0.14 | H29: 2018.243 | I29: 2164.7423 | J29: 2343.797 | K29: 2567.6153
G30: 0.15 | H30: 1846.1256 | I30: 1964.533 | J30: 2106.6218 | K30: 2280.286
G31: 0.16 | H31: 1700.7402 | I31: 1797.9405 | J31: 1912.8136 | K31: 2050.6613
B32: Calculation of Enterprise Value
B34: PV of FCFF | E34: =SUM(G17:K17) -> 724.71215
B35: PV of Terminal Value | E35: =E29*K15 -> 2251.7444
B36: Value of Operating Asset | E36: =SUM(E34:E35) -> 2976.4565
B38: Add: Cash | E38: ='Data Sheet'!K69 -> 989.65
B39: Less: Debt | E39: ='Main Financials'!J55 -> 343.38
B40: Value of Equity | E40: =E36+E38-E39 -> 3622.7265
B41: No. of Shares | E41: ='Data Sheet'!B6 -> 45.31637
B42: Value per Share | E42: =E40/E41 -> 79.943
B44: Market Price | E44: 309
B45: Multiple | E45: =E44/E42 -> 3.865254

Sheet DCF 2nd way
A4: x | B4: Ticker | C4: MARKSANS
A7: x | B7: Assumptions
B8: Valuation Assumptions
B9: WACC | D9: ='WACC-DCF'!J39 -> 0.12107404
B10: TGR | D10: 0.06
E11: 1 | F11: =E11+1 -> 2 | G11: =F11+1 -> 3 | H11: =G11+1 -> 4 | I11: =H11+1 -> 5 | J11: =I11+1 -> 6 | K11: =J11+1 -> 7 | L11: =K11+1 -> 8 | M11: =L11+1 -> 9 | N11: =M11+1 -> 10
A12: x | B12: Income Statement | E12: 2022 | F12: =E12+1 -> 2023 | G12: =F12+1 -> 2024 | H12: =G12+1 -> 2025 | I12: =H12+1 -> 2026 | J12: =I12+1 -> 2027 | K12: =J12+1 -> 2028 | L12: =K12+1 -> 2029 | M12: =L12+1 -> 2030 | N12: =M12+1 -> 2031
B13: Revenue | E13: ='Main Financials'!F11 -> 1490.84 | F13: ='Main Financials'!G11 -> 1852.14 | G13: ='Main Financials'!H11 -> 2177.41 | H13: ='Main Financials'!I11 -> 2622.85 | I13: ='Main Financials'!J11 -> 2950.94 | J13: {=TRANSPOSE(D75:D79)} -> 3326.109 | K13: 3695.2 | L13: 4064.291 | M13: 4433.382 | N13: 4802.473
B14: % growth | F14: =F13/E13-1 -> 0.2423466 | G14: =G13/F13-1 -> 0.17561847 | H14: =H13/G13-1 -> 0.20457332 | I14: =I13/H13-1 -> 0.12508912 | J14: =J13/I13-1 -> 0.12713542 | K14: =K13/J13-1 -> 0.1109678 | L14: =L13/K13-1 -> 0.099883903 | M14: =M13/L13-1 -> 0.090813133 | N14: =N13/M13-1 -> 0.083252695
B16: EBIT | E16: ='Main Financials'!F23-'Main Financials'!F29 -> 214.11 | F16: ='Main Financials'!G23-'Main Financials'!G29 -> 287.74 | G16: ='Main Financials'!H23-'Main Financials'!H29 -> 384.31 | H16: ='Main Financials'!I23-'Main Financials'!I29 -> 449.32 | I16: ='Main Financials'!J23-'Main Financials'!J29 -> 502.23 | J16: {=TRANSPOSE(I76:I80)} -> 588.888 | K16: 662.67 | L16: 736.452 | M16: 810.234 | N16: 884.016
B17: % of sales | E17: =E16/E13 -> 0.14361702 | F17: =F16/F13 -> 0.15535543 | G17: =G16/G13 -> 0.17649868 | H17: =H16/H13 -> 0.17130983 | I17: =I16/I13 -> 0.17019323 | J17: =J16/J13 -> 0.17705012 | K17: =K16/K13 -> 0.17933265 | L17: =L16/L13 -> 0.18120061 | ... N17: =N16/N13 -> 0.18407516
B19: Taxes | E19: ='Main Financials'!F35 -> 60.7 | F19: ='Main Financials'!G35 -> 72.33 | G19: ='Main Financials'!H35 -> 108.63 | H19: ='Main Financials'!I35 -> 121.35 | I19: ='Main Financials'!J35 -> 140.49 | J19: {=TRANSPOSE(L76:L80)} -> 163.28 | K19: 184.14 | L19: 205 | M19: 225.86 | N19: 246.72
B20: % of EBIT | E20: =E19/E16 -> 0.28349914 | F20: =F19/F16 -> 0.25137277 | G20: =G19/G16 -> 0.28266243 | H20: =H19/H16 -> 0.27007478 | I20: =I19/I16 -> 0.27973239 | J20: =J19/J16 -> 0.27726834 | K20: =K19/K16 -> 0.27787587 | L20: =L19/L16 -> 0.27836166 | ... N20: =N19/N16 -> 0.27908997
A22: x | B22: Cash Flow Items | E22: =E12 -> 2022 | F22: =E22+1 -> 2023 | G22: =F22+1 -> 2024 | H22: =G22+1 -> 2025 | I22: =H22+1 -> 2026 | J22: =I22+1 -> 2027 | K22: =J22+1 -> 2028 | L22: =K22+1 -> 2029 | M22: =L22+1 -> 2030 | N22: =M22+1 -> 2031
B23: D&A | E23: ='Main Financials'!F29 -> 44.78 | F23: ='Main Financials'!G29 -> 51.85 | G23: ='Main Financials'!H29 -> 74.27 | H23: ='Main Financials'!I29 -> 83.39 | I23: ='Main Financials'!J29 -> 98.63 | J23: {=TRANSPOSE(C90:C94)} -> 112.356 | K23: 126.28 | L23: 140.204 | M23: 154.128 | N23: 168.052
B24: % of sales | E24: =E23/E13 -> 0.030036758 | F24: =F23/F13 -> 0.027994644 | G24: =G23/G13 -> 0.034109332 | H24: =H23/H13 -> 0.03179366 | I24: =I23/I13 -> 0.033423248 | J24: =J23/J13 -> 0.033780011 | K24: =K23/K13 -> 0.034174064 | L24: =L23/L13 -> 0.034496546 | ... N24: =N23/N13 -> 0.034992805
B26: CapEx | E26: =-'Main Financials'!F88-'Main Financials'!F90 -> 46 | F26: =-'Main Financials'!G88-'Main Financials'!G90 -> 54 | G26: =-'Main Financials'!H88-'Main Financials'!H90 -> 246 | H26: =-'Main Financials'!I88-'Main Financials'!I90 -> 173 | I26: =-'Main Financials'!J88-'Main Financials'!J90 -> 280 | J26: {=TRANSPOSE(F90:F94)} -> 335.9 | K26: 394.6 | L26: 453.3 | M26: 512 | N26: 570.7
B27: % of sales | E27: =E26/E13 -> 0.030855088 | F27: =F26/F13 -> 0.029155463 | G27: =G26/G13 -> 0.11297826 | H27: =H26/H13 -> 0.065958785 | I27: =I26/I13 -> 0.09488502 | J27: =J26/J13 -> 0.10098887 | K27: =K26/K13 -> 0.10678718 | L27: =L26/L13 -> 0.11153237 | ... N27: =N26/N13 -> 0.11883461
B29: Change in NWC | E29: ='Intrinsic Growth'!E44 -> 0 | F29: ='Intrinsic Growth'!F44 -> 124 | G29: ='Intrinsic Growth'!G44 -> 168 | H29: ='Intrinsic Growth'!H44 -> 254 | I29: ='Intrinsic Growth'!I44 -> 205 | J29: =I29 -> 205 | K29: =J29 -> 205 | L29: =K29 -> 205 | M29: =L29 -> 205 | N29: =M29 -> 205
B30: % of sales | E30: =E29/E13 -> 0 | F30: =F29/F13 -> 0.066949583 | G30: =G29/G13 -> 0.077155887 | H30: =H29/H13 -> 0.096841222 | I30: =I29/I13 -> 0.069469389 | J30: =J29/J13 -> 0.061633578 | K30: =K29/K13 -> 0.055477376 | L30: =L29/L13 -> 0.050439302 | ... N30: =N29/N13 -> 0.042686341
J31: 1 | K31: =J31+1 -> 2 | L31: =K31+1 -> 3 | M31: =L31+1 -> 4 | N31: =M31+1 -> 5
A32: x | B32: DCF | E32: =E22 -> 2022 | F32: =F22 -> 2023 | G32: =G22 -> 2024 | H32: =H22 -> 2025 | I32: =I22 -> 2026 | J32: =J22 -> 2027 | K32: =K22 -> 2028 | L32: =L22 -> 2029 | ... N32: =N22 -> 2031
B33: Revenue | E33: =E13 -> 1490.84 | F33: =F13 -> 1852.14 | G33: =G13 -> 2177.41 | H33: =H13 -> 2622.85 | I33: =I13 -> 2950.94 | J33: =J13 -> 3326.109 | K33: =K13 -> 3695.2 | L33: =L13 -> 4064.291 | ... N33: =N13 -> 4802.473
B34: % growth | F34: =F14 -> 0.2423466 | G34: =G14 -> 0.17561847 | H34: =H14 -> 0.20457332 | I34: =I14 -> 0.12508912 | J34: =J14 -> 0.12713542 | K34: =K14 -> 0.1109678 | L34: =L14 -> 0.099883903 | M34: =M14 -> 0.090813133 | N34: =N14 -> 0.083252695
B36: EBIT | E36: =E16 -> 214.11 | F36: =F16 -> 287.74 | G36: =G16 -> 384.31 | H36: =H16 -> 449.32 | I36: =I16 -> 502.23 | J36: =J16 -> 588.888 | K36: =K16 -> 662.67 | L36: =L16 -> 736.452 | ... N36: =N16 -> 884.016
B37: % margin | F37: =F17 -> 0.15535543 | G37: =G17 -> 0.17649868 | H37: =H17 -> 0.17130983 | I37: =I36/I33 -> 0.17019323 | J37: =J17 -> 0.17705012 | K37: =K17 -> 0.17933265 | L37: =L17 -> 0.18120061 | M37: =M17 -> 0.18275754 | N37: =N17 -> 0.18407516
B39: Taxes | E39: =E19 -> 60.7 | F39: =F19 -> 72.33 | G39: =G19 -> 108.63 | H39: =H19 -> 121.35 | I39: =I19 -> 140.49 | J39: =J19 -> 163.28 | K39: =K19 -> 184.14 | L39: =L19 -> 205 | ... N39: =N19 -> 246.72
B40: % of EBIT | F40: =F20 -> 0.25137277 | G40: =G20 -> 0.28266243 | H40: =H20 -> 0.27007478 | I40: =I20 -> 0.27973239 | J40: =J20 -> 0.27726834 | K40: =K20 -> 0.27787587 | L40: =L20 -> 0.27836166 | M40: =M20 -> 0.27875898 | N40: =N20 -> 0.27908997
B42: EBIAT | J42: =J36-J39 -> 425.608 | K42: =K36-K39 -> 478.53 | L42: =L36-L39 -> 531.452 | M42: =M36-M39 -> 584.374 | N42: =N36-N39 -> 637.296
B44: D&A | J44: =J23 -> 112.356 | K44: =K23 -> 126.28 | L44: =L23 -> 140.204 | M44: =M23 -> 154.128 | N44: =N23 -> 168.052
B45: % of sales | J45: =J24 -> 0.033780011 | K45: =K24 -> 0.034174064 | L45: =L24 -> 0.034496546 | M45: =M24 -> 0.034765333 | N45: =N24 -> 0.034992805
B47: CapEx | J47: =J26 -> 335.9 | K47: =K26 -> 394.6 | L47: =L26 -> 453.3 | M47: =M26 -> 512 | N47: =N26 -> 570.7
B48: % of sales | J48: =J27 -> 0.10098887 | K48: =K27 -> 0.10678718 | L48: =L27 -> 0.11153237 | M48: =M27 -> 0.11548745 | N48: =N27 -> 0.11883461
B50: Change in NWC | J50: =J29 -> 205 | K50: =K29 -> 205 | L50: =L29 -> 205 | M50: =M29 -> 205 | N50: =N29 -> 205
B51: % of sales | J51: =J30 -> 0.061633578 | K51: =K30 -> 0.055477376 | L51: =L30 -> 0.050439302 | M51: =M30 -> 0.046240094 | N51: =N30 -> 0.042686341
B53: Unlevered FCF | J53: =J42+J44-J47-J50 -> -2.936 | K53: =K42+K44-K47-K50 -> 5.21 | L53: =L42+L44-L47-L50 -> 13.356 | M53: =M42+M44-M47-M50 -> 21.502 | N53: =N42+N44-N47-N50 -> 29.648
B54: Present Value of FCF | J54: =J53/(1+wacc)^J31 -> -2.6189171 | K54: =K53/(1+wacc)^K31 -> 4.1454256 | L54: =L53/(1+wacc)^L31 -> 9.47924 | M54: =M53/(1+wacc)^M31 -> 13.612618 | N54: =N53/(1+wacc)^N31 -> 16.742639
A56: x | B56: Terminal Value | N56: =N53*(1+tgr)/(wacc-tgr) -> 514.57014
B57: Present Value of Terminal Value | N57: =N56/(1+wacc)^I11 -> 290.58494
B58: Enterprise Value | N58: =N57+M54+L54+K54+J54+N54 -> 331.94594
...

Sheet Data ->

Sheet compdata
B2: S.No. | C2: Company | D2: CMP Rs. | E2: No. Eq. Shares Cr. | F2: Market Cap | G2: Debt Rs.Cr. | H2: Cash End Rs.Cr. | I2: Net Debt | J2: EV | K2: EBITDA | L2: Sales Rs.Cr. | M2: NP 12M Rs.Cr.
B3: 1 | C3: Sun Pharma.Inds. | D3: 1760 | E3: 239.93 | F3: =E3*D3 -> 422276.8 | G3: 4627.32 | H3: 11603.08 | I3: =G3-H3 -> -6975.76 | J3: =F3+G3-H3 -> 415301.04 | K3: =1/(F18)*J3 -> 20082.255 | L3: 59910.52 | M3: 12117.01
B4: 2 | C4: Divi's Lab. | D4: 9340 | E4: 26.55 | F4: =E4*D4 -> 247977 | G4: 7 | H4: 3414 | I4: =G4-H4 -> -3407 | J4: =F4+G4-H4 -> 244570 | K4: =1/(F19)*J4 -> 4419.4073 | L4: 11230 | M4: 2925
B5: 3 | C5: Torrent Pharma. | D5: 4656.9 | E5: 38.04 | F5: =E5*D5 -> 177148.48 | G5: 15025.5 | H5: 1165.2 | I5: =G5-H5 -> 13860.3 | J5: =F5+G5-H5 -> 191008.78 | K5: =1/(F20)*J5 -> 5122.252 | L5: 15723 | M5: 2156
B6: 4 | C6: Zydus Lifesci. | D6: 1117.5 | E6: 99.75 | F6: =E6*D6 -> 111470.62 | G6: 12496 | H6: 1416.6 | I6: =G6-H6 -> 11079.4 | J6: =F6+G6-H6 -> 122550.02 | K6: =1/(F21)*J6 -> 8778.6551 | L6: 28591.7 | M6: 4592.7
B7: 5 | C7: Laurus Labs | D7: 2036.6 | E7: 54.03 | F7: =E7*D7 -> 110037.5 | G7: 2518.48 | H7: 113.7 | I7: =G7-H7 -> 2404.78 | J7: =F7+G7-H7 -> 112442.28 | K7: =1/(F22)*J7 -> 2087.6769 | L7: 7269.64 | M7: 1090.53
B8: 6 | C8: Cipla | D8: 1301 | E8: 80.79 | F8: =E8*D8 -> 105107.79 | G8: 613.77 | H8: 1307.42 | I8: =G8-H8 -> -693.65 | J8: =F8+G8-H8 -> 104414.14 | K8: =1/(F23)*J8 -> 6131.1885 | L8: 28324.4 | M8: 3355.68
B9: 7 | C9: Dr Reddy's Labs | D9: 1197 | E9: 83.47 | F9: =E9*D9 -> 99913.59 | G9: 7734.1 | H9: 3348.7 | I9: =G9-H9 -> 4385.4 | J9: =F9+G9-H9 -> 104298.99 | K9: =1/(F24)*J9 -> 6576.2289 | L9: 33227.9 | M9: 3183.3
B10: 8 | C10: Marksans Pharma | D10: 309.1 | E10: 45.32 | F10: =E10*D10 -> 14008.412 | G10: 343.38 | H10: 989.65 | I10: =G10-H10 -> -646.27 | J10: =F10+G10-H10 -> 13362.142 | K10: =1/(F25)*J10 -> 816.25791 | L10: 3171.75 | M10: 521.27
B17: S.No. | C17: Company | D17: CMP Rs. | E17: EBIT 12M Rs.Cr. | F17: EV / EBITDA | G17: Dep 12M Rs.Cr.
B18: 1 | C18: Sun Pharma.Inds. | D18: 1760 | E18: 17102.27 | F18: 20.68 | G18: 2976.02
B19: 2 | C19: Divi's Lab. | D19: 9340 | E19: 3935 | F19: 55.34 | G19: 484
B20: 3 | C20: Torrent Pharma. | D20: 4656.9 | E20: 3611 | F20: 37.29 | G20: 1511
B21: 4 | C21: Zydus Lifesci. | D21: 1117.5 | E21: 7052.1 | F21: 13.96 | G21: 1724.6
B22: 5 | C22: Laurus Labs | D22: 2036.6 | E22: 1600.47 | F22: 53.86 | G22: 487.08
B23: 6 | C23: Cipla | D23: 1301 | E23: 4868.91 | F23: 17.03 | G23: 1262.5
B24: 7 | C24: Dr Reddy's Labs | D24: 1197 | E24: 4457.3 | F24: 15.86 | G24: 2119.3
B25: 8 | C25: Marksans Pharma | D25: 309.1 | E25: 715.6 | F25: 16.37 | G25: 100.4

Sheet Data Sheet
A1: COMPANY NAME | B1: MARKSANS PHARMA LTD | E1: =IF(B2<>B3, "A NEW VERSION OF THE WORKSHEET IS AVAILABLE", "")
A2: LATEST VERSION | B2: 2.1 | E2: PLEASE DO NOT MAKE ANY CHANGES TO THIS SHEET
A3: CURRENT VERSION | B3: 2.1
A5: META
A6: Number of shares | B6: =IF(B9>0, B9/B8, 0) -> 45.31637
A7: Face Value | B7: 1
A8: Current Price | B8: 325.6
A9: Market Capitalization | B9: 14755.01
A15: PROFIT & LOSS
A16: Report Date | B16: 42825 | C16: 43190 | D16: 43555 | E16: 43921 | F16: 44286 | G16: 44651 | H16: 45016 | I16: 45382 | J16: 45747 | K16: 46112
A17: Sales | B17: 767.16 | C17: 912.69 | D17: 1000.07 | E17: 1134.21 | F17: 1376.18 | G17: 1490.84 | H17: 1852.14 | I17: 2177.41 | J17: 2622.85 | K17: 2950.94
A18: Raw Material Cost | B18: 506.68 | C18: 502.58 | D18: 517.91 | E18: 514.88 | F18: 731.33 | G18: 703.92 | H18: 927.75 | I18: 1111.98 | J18: 1327.5 | K18: 1413.7
A19: Change in Inventory | B19: 47.94 | C19: -20.55 | D19: 19.9 | E19: -52.95 | F19: 136.28 | G19: -12.9 | H19: 6.39 | I19: 73.86 | J19: 183.76 | K19: 136.42
A20: Power and Fuel | B20: 12.97 | C20: 11.55 | D20: 13.99 | E20: 14 | F20: 16.42 | G20: 18.59 | H20: 24.5 | I20: 36.94 | J20: 40.08 | K20: 54.08
A21: Other Mfr. Exp | B21: 33.63 | C21: 42.45 | D21: 49.3 | E21: 32.13 | F21: 34.04 | G21: 12.73 | H21: 18.74 | I21: 87.3 | J21: 140.08 | K21: 155.88
A22: Employee Cost | B22: 149.7 | C22: 147.75 | D22: 159.07 | E22: 168.42 | F22: 197.32 | G22: 220.3 | H22: 239.37 | I22: 293.64 | J22: 350.3 | K22: 420.93
A23: Selling and admin | B23: 65.18 | C23: 88.83 | D23: 109.58 | E23: 120.38 | F23: 154.55 | G23: 148.41 | H23: 144.74 | I23: 236.41 | J23: 374.24 | K23: 370.25
A24: Other Expenses | B24: 2.21 | C24: 20.54 | D24: 37.98 | E24: 39.2 | F24: 39.17 | G24: 115.1 | H24: 163.84 | I24: 26.42 | J24: 41.7 | K24: 71.66
A25: Other Income | B25: 7.04 | C25: 8.42 | D25: 4.63 | E25: 0.33 | F25: 6.68 | G25: 41.85 | H25: 59.05 | I25: 50.42 | J25: 66.3 | K25: 82.46
A26: Depreciation | B26: 30.09 | C26: 26.84 | D26: 22.8 | E26: 26.66 | F26: 36.15 | G26: 44.78 | H26: 51.85 | I26: 74.27 | J26: 83.39 | K26: 98.63
A27: Interest | B27: 6.78 | C27: 10.22 | D27: 9.66 | E27: 8.75 | F27: 7.99 | G27: 8.45 | H27: 9.13 | I27: 11.2 | J27: 11.66 | K27: 24.13
... A31: Dividend Amount | B31: 2.05 | C31: 2.05 | D31: 2.05 | E31: 4.09 | F31: 10.23 | G31: 10.23 | H31: 22.66 | I31: 27.19 | J31: 36.26 | K31: 40.79
A40: Quarters
A41: Report Date | B41: 45382 | C41: 45473 | D41: 45565 | E41: 45657 | F41: 45747 | G41: 45838 | H41: 45930 | I41: 46022 | J41: 46112 | K41: 46203
A42: Sales | B42: 560.01 | C42: 590.62 | D42: 641.92 | E42: 681.85 | F42: 708.46 | G42: 619.99 | H42: 720.41 | I42: 754.43 | J42: 856.11 | K42: 840.8
A43: Expenses | B43: 450.37 | C43: 462.19 | D43: 495.11 | E43: 543.08 | F43: 581.52 | G43: 519.86 | H43: 575.91 | I43: 593.68 | J43: 660.68 | K43: 627.76
A44: Other Income | B44: 16.53 | C44: 14.95 | D44: -0.07 | E44: 27.85 | F44: 15.34 | G44: 5.64 | H44: 21.57 | I44: 20.14 | J44: 35.17 | K44: 25.4
A45: Depreciation | B45: 21.06 | C45: 20.44 | D45: 19.51 | E45: 20.69 | F45: 22.74 | G45: 23.1 | H45: 26.92 | I45: 24.33 | J45: 24.29 | K45: 24.86
A46: Interest | B46: 4.84 | C46: 2.92 | D46: 2.63 | E46: 2.67 | F46: 3.44 | G46: 6.07 | H46: 5.82 | I46: 5.94 | J46: 6.31 | K46: 7
A47: Profit before tax | B47: 100.27 | C47: 120.02 | D47: 124.6 | E47: 143.26 | F47: 116.1 | G47: 76.6 | H47: 133.33 | I47: 150.62 | J47: 200 | K47: 206.58
A48: Tax | B48: 22.63 | C48: 30.95 | D48: 26.84 | E48: 38.19 | F48: 25.37 | G48: 18.4 | H48: 34.2 | I48: 36.94 | J48: 50.97 | K48: 47.16
A49: Net profit | B49: 78.29 | C49: 88.75 | D49: 96.72 | E49: 104.56 | F49: 90.55 | G49: 58.32 | H49: 98.25 | I49: 113.2 | J49: 148.13 | K49: 157.17
A50: Operating Profit | B50: 109.64 | C50: 128.43 | D50: 146.81 | E50: 138.77 | F50: 126.94 | G50: 100.13 | H50: 144.5 | I50: 160.75 | J50: 195.43 | K50: 213.04
A55: BALANCE SHEET
A56: Report Date | B56: 42825 | C56: 43190 | D56: 43555 | E56: 43921 | F56: 44286 | G56: 44651 | H56: 45016 | I56: 45382 | J56: 45747 | K56: 46112
A57: Equity Share Capital | B57: 40.93 | C57: 40.93 | D57: 40.93 | E57: 40.93 | F57: 40.93 | G57: 40.93 | H57: 45.32 | I57: 45.32 | J57: 45.32 | K57: 45.32
A58: Reserves | B58: 392.5 | C58: 429.93 | D58: 501.55 | E58: 595.08 | F58: 845.56 | G58: 1161.34 | H58: 1699.85 | I58: 2019.74 | J58: 2421.6 | K58: 2977.84
A59: Borrowings | B59: 109.71 | C59: 117.96 | D59: 100.22 | E59: 29.65 | F59: 34.1 | G59: 110.78 | H59: 122.95 | I59: 244.06 | J59: 321.91 | K59: 343.38
A60: Other Liabilities | B60: 208.67 | C60: 141.92 | D60: 159.76 | E60: 236.37 | F60: 307.43 | G60: 323.2 | H60: 322.27 | I60: 371.84 | J60: 450.81 | K60: 489.27
A61: Total | B61: 751.81 | C61: 730.74 | D61: 802.46 | E61: 902.03 | F61: 1228.02 | G61: 1636.25 | H61: 2190.39 | I61: 2680.96 | J61: 3239.64 | K61: 3855.81
...

Sheet BS
B2: Particulars | C2: 42064 | D2: 42430 | E2: 42795 | F2: 43160 | G2: 43525 | H2: 43891 | I2: 44256 | J2: 44621 | K2: 44986 | L2: 45352 | M2: 45717 | N2: 46082
B4: Equity Capital | C4: 41 | D4: 41 | E4: 41 | F4: 41 | G4: 41 | H4: 41 | I4: 41 | J4: 41 | K4: 45 | L4: 45 | M4: 45 | N4: 45
B5: Reserves | C5: 326 | D5: 401 | E5: 392 | F5: 430 | G5: 502 | H5: 595 | I5: 846 | J5: 1161 | K5: 1700 | L5: 2020 | M5: 2422 | N5: 2978
B6: Borrowings -
B7: Short term Borrowings | C7: 82 | D7: 88 | E7: 110 | F7: 117 | G7: 100 | H7: 19 | I7: 19 | J7: 41 | K7: 42 | L7: 29 | M7: 23 | N7: 30
B8: Lease Liabilities | C8: 0 | D8: 0 | E8: 0 | F8: 0 | G8: 0 | H8: 11 | I8: 15 | J8: 69 | K8: 81 | L8: 215 | M8: 299 | N8: 314
B9: Preference Capital | C9: 12 | D9: 12 | E9: 0 | F9: 0 | G9: 0 | H9: 0 | I9: 0 | J9: 0 | K9: 0 | L9: 0 | M9: 0 | N9: 0
B10: Other Borrowings | C10: 6 | D10: 0 | E10: 0 | F10: 1 | G10: 0 | H10: 0 | I10: 0 | J10: 0 | K10: 0 | L10: 0 | M10: 0 | N10: 0
B11: Other Liabilities -
B12: Non controlling int | C12: 8 | D12: 8 | E12: 6 | F12: 10 | G12: 10 | H12: 13 | I12: 19 | J12: 21 | K12: 20 | L12: 21 | M12: 22 | N12: 30
B13: Trade Payables | C13: 107 | D13: 119 | E13: 162 | F13: 78 | G13: 106 | H13: 110 | I13: 169 | J13: 200 | K13: 231 | L13: 268 | M13: 306 | N13: 337
B14: Advance from Customers | C14: 0 | D14: 0 | E14: 0 | F14: 0 | G14: 0 | H14: 0 | I14: 1 | J14: 2 | K14: 1 | L14: 2 | M14: 1 | N14: 2
B15: Other liability items | C15: 92 | D15: 53 | E15: 41 | F15: 55 | G15: 43 | H15: 113 | I15: 119 | J15: 101 | K15: 71 | L15: 81 | M15: 121 | N15: 121
B16: Total Liabilities | C16: 676 | D16: 722 | E16: 752 | F16: 731 | G16: 802 | H16: 902 | I16: 1228 | J16: 1636 | K16: 2190 | L16: 2681 | M16: 3240 | N16: 3856
B18: Fixed Assets -
B19: Land | C19: 1 | D19: 1 | E19: 1 | F19: 1 | G19: 1 | H19: 0 | I19: 9 | J19: 1 | K19: 1 | L19: 23 | M19: 23 | N19: 23
B20: Building | C20: 51 | D20: 89 | E20: 97 | F20: 121 | G20: 123 | H20: 126 | I20: 132 | J20: 226 | K20: 270 | L20: 483 | M20: 625 | N20: 692
B21: Plant Machinery | C21: 99 | D21: 130 | E21: 136 | F21: 145 | G21: 165 | H21: 197 | I21: 235 | J21: 287 | K21: 307 | L21: 421 | M21: 531 | N21: 604
B22: Equipments | C22: 1 | D22: 2 | E22: 2 | F22: 3 | G22: 3 | H22: 4 | I22: 4 | J22: 4 | K22: 5 | L22: 5 | M22: 5 | N22: 6
B23: Computers | C23: 3 | D23: 5 | E23: 5 | F23: 6 | G23: 6 | H23: 6 | I23: 7 | J23: 7 | K23: 7 | L23: 12 | M23: 13 | N23: 16
B24: Furniture n fittings | C24: 3 | D24: 5 | E24: 5 | F24: 6 | G24: 7 | H24: 9 | I24: 9 | J24: 11 | K24: 16 | L24: 21 | M24: 29 | N24: 33
B25: Vehicles | C25: 6 | D25: 7 | E25: 7 | F25: 8 | G25: 8 | H25: 8 | I25: 9 | J25: 10 | K25: 10 | L25: 11 | M25: 11 | N25: 16
B26: Intangible Assets | C26: 45 | D26: 102 | E26: 102 | F26: 102 | G26: 75 | H26: 75 | I26: 20 | J26: 30 | K26: 38 | L26: 60 | M26: 61 | N26: 68
B27: Other fixed assets | C27: 88 | D27: 88 | E27: 101 | F27: 104 | G27: 119 | H27: 138 | I27: 128 | J27: 150 | K27: 174 | L27: 158 | M27: 114 | N27: 148
B28: Gross Block | C28: 298 | D28: 429 | E28: 456 | F28: 495 | G28: 506 | H28: 563 | I28: 552 | J28: 726 | K28: 828 | L28: 1193 | M28: 1413 | N28: 1605
B29: Accumulated Depreciation | C29: 132 | D29: 160 | E29: 190 | F29: 216 | G29: 237 | H29: 261 | I29: 243 | J29: 298 | K29: 342 | L29: 418 | M29: 431 | N29: 561
B30: CWIP | C30: 0 | D30: 0 | E30: 0 | F30: 0 | G30: 0 | H30: 0 | I30: 12 | J30: 3 | K30: 10 | L30: 9 | M30: 27 | N30: 59
B31: Investments | C31: 0 | D31: 0 | E31: 0 | F31: 0 | G31: 0 | H31: 0 | I31: 0 | J31: 0 | K31: 1 | L31: 27 | M31: 1 | N31: 0
B32: Other Assets -
B33: Inventories | C33: 130 | D33: 168 | E33: 190 | F33: 218 | G33: 293 | H33: 242 | I33: 404 | J33: 424 | K33: 485 | L33: 618 | M33: 846 | N33: 972
B34: Trade receivables | C34: 183 | D34: 217 | E34: 248 | F34: 177 | G34: 177 | H34: 243 | I34: 272 | J34: 395 | K34: 417 | L34: 453 | M34: 540 | N34: 645
B35: Cash Equivalents | C35: 185 | D35: 35 | E35: 25 | F35: 40 | G35: 34 | H35: 94 | I35: 212 | J35: 349 | K35: 715 | L35: 674 | M35: 704 | N35: 990
B36: Loans n Advances | C36: 0 | D36: 0 | E36: 0 | F36: 0 | G36: 0 | H36: 3 | I36: 1 | J36: 21 | K36: 29 | L36: 38 | M36: 55 | N36: 65
B37: Other asset items | C37: 11 | D37: 32 | E37: 22 | F37: 16 | G37: 29 | H37: 17 | I37: 17 | J37: 15 | K37: 48 | L37: 86 | M37: 85 | N37: 81
B38: Total Assets | C38: 676 | D38: 722 | E38: 752 | F38: 731 | G38: 802 | H38: 902 | I38: 1228 | J38: 1636 | K38: 2190 | L38: 2681 | M38: 3240 | N38: 3856

Sheet Beta
B2: Regression Beta - 2 Years Weekly
B4: marksan past 2 year weekly returns | F4: nifty 50 past 2 year weekly returns | J4: Beta Drifting
N6: BETA 1 | O6: =SLOPE(D9:D112,G9:G112) -> 1.2084444
